<?xml version="1.0" ?>
<!-- =================================================================================== -->
<!-- |    This document was autogenerated by xacro from ur_description/urdf/ur5_robot.urdf.xacro | -->
<!-- |    EDITING THIS FILE BY HAND IS NOT RECOMMENDED                                 | -->
<!-- =================================================================================== -->
<robot name="ur5_robotiq" xmlns:xacro="http://ros.org/wiki/xacro">

  <material name="LightGrey">
    <color rgba="0.7 0.7 0.7 1.0"/>
  </material>

  <material name="DarkGrey">
    <color rgba="0.3 0.3 0.3 1.0"/>
  </material>

  <material name="Blanc">
    <color rgba="1.0 1.0 1.0 1.0"/>
  </material>

  <material name="Tactile_1">
    <color rgba="0.8 0.0 0.0 1.0"/>
  </material>

  <material name="Tactile_2">
    <color rgba="0.7 0.2 0.5 1.0"/>
  </material>

  <link name="world"/>

  <!-- ######################################### UR5 ####################################### -->
  <joint name="world_joint" type="fixed">
    <parent link="world"/>
    <child link="base_link"/>
    <origin rpy="0.0 0.0 0.0" xyz="0.0 0.0 0.0"/>
  </joint>

  <link name="base_link">
    <visual>
      <geometry>
        <mesh filename="visual/base.stl"/>
      </geometry>
      <material name="LightGrey" />
    </visual>
    <collision>
      <geometry>
        <mesh filename="collision/base.stl"/>
      </geometry>
    </collision>
    <inertial>
      <mass value="4.0"/>
      <origin rpy="0 0 0" xyz="0.0 0.0 0.0"/>
      <inertia ixx="0.00443333156" ixy="0.0" ixz="0.0" iyy="0.00443333156" iyz="0.0" izz="0.0072"/>
    </inertial>
  </link>

  <!-- Fix orientation of robot base around z axis by 180 degrees to match real robot -->
  <link name="base_fix">
    <inertial>
      <mass value="0.0"/>
      <origin rpy="0 0 0" xyz="0.0 0.0 0.0"/>
      <inertia ixx="0.0" ixy="0.0" ixz="0.0" iyy="0.0" iyz="0.0" izz="0.0"/>
    </inertial>
  </link>

  <joint name="base_link_fix" type="fixed">
    <origin rpy="0 0 -3.14159265359" xyz="0 0 0"/>
    <parent link="base_link"/>
    <child link="base_fix"/>
  </joint>

  <joint name="shoulder_pan_joint" type="revolute">
    <parent link="base_fix"/>
    <child link="shoulder_link"/>
    <origin rpy="0.0 0.0 0.0" xyz="0.0 0.0 0.089159"/>
    <axis xyz="0 0 1"/>
    <limit effort="150.0" lower="-6.28318530718" upper="6.28318530718" velocity="3.15"/>
    <dynamics damping="0.0" friction="0.0"/>
  </joint>

  <link name="shoulder_link">
    <visual>
      <geometry>
        <mesh filename="visual/shoulder.stl"/>
      </geometry>
      <material name="DarkGrey" />
    </visual>
    <collision>
      <geometry>
        <mesh filename="collision/shoulder.stl"/>
      </geometry>
    </collision>
    <inertial>
      <mass value="3.7"/>
      <origin rpy="0 0 0" xyz="0.0 0.0 0.0"/>
      <inertia ixx="0.010267495893" ixy="0.0" ixz="0.0" iyy="0.010267495893" iyz="0.0" izz="0.00666"/>
    </inertial>
  </link>

  <joint name="shoulder_lift_joint" type="revolute">
    <parent link="shoulder_link"/>
    <child link="upper_arm_link"/>
    <origin rpy="0.0 1.57079632679 0.0" xyz="0.0 0.13585 0.0"/>
    <axis xyz="0 1 0"/>
    <limit effort="150.0" lower="-6.28318530718" upper="6.28318530718" velocity="3.15"/>
    <dynamics damping="0.0" friction="0.0"/>
  </joint>

  <link name="upper_arm_link">
    <visual>
      <geometry>
        <mesh filename="visual/upperarm.stl"/>
      </geometry>
      <material name="LightGrey" />
    </visual>
    <collision>
      <geometry>
        <mesh filename="collision/upperarm.stl"/>
      </geometry>
    </collision>
    <inertial>
      <mass value="8.393"/>
      <origin rpy="0 0 0" xyz="0.0 0.0 0.28"/>
      <inertia ixx="0.22689067591" ixy="0.0" ixz="0.0" iyy="0.22689067591" iyz="0.0" izz="0.0151074"/>
    </inertial>
  </link>

  <joint name="elbow_joint" type="revolute">
    <parent link="upper_arm_link"/>
    <child link="forearm_link"/>
    <origin rpy="0.0 0.0 0.0" xyz="0.0 -0.1197 0.425"/>
    <axis xyz="0 1 0"/>
    <limit effort="150.0" lower="-3.14159265359" upper="3.14159265359" velocity="3.15"/>
    <dynamics damping="0.0" friction="0.0"/>
  </joint>

  <link name="forearm_link">
    <visual>
      <geometry>
        <mesh filename="visual/forearm.stl"/>
      </geometry>
      <material name="DarkGrey" />
    </visual>
    <collision>
      <geometry>
        <mesh filename="collision/forearm.stl"/>
      </geometry>
    </collision>
    <inertial>
      <mass value="2.275"/>
      <origin rpy="0 0 0" xyz="0.0 0.0 0.25"/>
      <inertia ixx="0.049443313556" ixy="0.0" ixz="0.0" iyy="0.049443313556" iyz="0.0" izz="0.004095"/>
    </inertial>
  </link>

  <joint name="wrist_1_joint" type="revolute">
    <parent link="forearm_link"/>
    <child link="wrist_1_link"/>
    <origin rpy="0.0 1.57079632679 0.0" xyz="0.0 0.0 0.39225"/>
    <axis xyz="0 1 0"/>
    <limit effort="28.0" lower="-6.28318530718" upper="6.28318530718" velocity="3.2"/>
    <dynamics damping="0.0" friction="0.0"/>
  </joint>

  <link name="wrist_1_link">
    <visual>
      <geometry>
        <mesh filename="visual/wrist1.stl"/>
      </geometry>
      <material name="LightGrey" />
    </visual>
    <collision>
      <geometry>
        <mesh filename="collision/wrist1.stl"/>
      </geometry>
    </collision>
    <inertial>
      <mass value="1.219"/>
      <origin rpy="0 0 0" xyz="0.0 0.0 0.0"/>
      <inertia ixx="0.111172755531" ixy="0.0" ixz="0.0" iyy="0.111172755531" iyz="0.0" izz="0.21942"/>
    </inertial>
  </link>

  <joint name="wrist_2_joint" type="revolute">
    <parent link="wrist_1_link"/>
    <child link="wrist_2_link"/>
    <origin rpy="0.0 0.0 0.0" xyz="0.0 0.093 0.0"/>
    <axis xyz="0 0 1"/>
    <limit effort="28.0" lower="-6.28318530718" upper="6.28318530718" velocity="3.2"/>
    <dynamics damping="0.0" friction="0.0"/>
  </joint>

  <link name="wrist_2_link">
    <visual>
      <geometry>
        <mesh filename="visual/wrist2.stl"/>
      </geometry>
      <material name="DarkGrey" />
    </visual>
    <collision>
      <geometry>
        <mesh filename="collision/wrist2.stl"/>
      </geometry>
    </collision>
    <inertial>
      <mass value="1.219"/>
      <origin rpy="0 0 0" xyz="0.0 0.0 0.0"/>
      <inertia ixx="0.111172755531" ixy="0.0" ixz="0.0" iyy="0.111172755531" iyz="0.0" izz="0.21942"/>
    </inertial>
  </link>

  <joint name="wrist_3_joint" type="revolute">
    <parent link="wrist_2_link"/>
    <child link="wrist_3_link"/>
    <origin rpy="0.0 0.0 0.0" xyz="0.0 0.0 0.09465"/>
    <axis xyz="0 1 0"/>
    <limit effort="28.0" lower="-6.28318530718" upper="6.28318530718" velocity="3.2"/>
    <dynamics damping="0.0" friction="0.0"/>
  </joint>

  <link name="wrist_3_link">
    <visual>
      <geometry>
        <mesh filename="visual/wrist3.stl"/>
      </geometry>
      <material name="LightGrey">
        <color rgba="0.7 0.7 0.7 1.0"/>
      </material>
    </visual>
    <collision>
      <geometry>
        <mesh filename="collision/wrist3.stl"/>
      </geometry>
    </collision>
    <inertial>
      <mass value="0.1879"/>
      <origin rpy="0 0 0" xyz="0.0 0.0 0.0"/>
      <inertia ixx="0.0171364731454" ixy="0.0" ixz="0.0" iyy="0.0171364731454" iyz="0.0" izz="0.033822"/>
    </inertial>
  </link>

  <joint name="ee_fixed_joint" type="fixed">
    <parent link="wrist_3_link"/>
    <child link="ee_link"/>
    <origin rpy="-1.57079632679 0.0 0.0" xyz="0.0 0.0823 0.0"/>
  </joint>

  <link name="ee_link">
    <visual>
      <geometry>
        <box size="0.01 0.01 0.01"/>
      </geometry>
      <origin rpy="0 0 0" xyz="0 0 0"/>
    </visual>
    <inertial>
      <mass value="0.0"/>
      <origin rpy="0 0 0" xyz="0.0 0.0 0.0"/>
      <inertia ixx="0.0" ixy="0.0" ixz="0.0" iyy="0.0" iyz="0.0" izz="0.0"/>
    </inertial>
  </link>

  <joint name="tool_fixed_joint" type="fixed">
    <parent link="ee_link"/>
    <child link="tool_link"/>
    <origin rpy="0.0 0.0 0.0" xyz="0.0 0.0 0.15"/>
  </joint>

  <link name="tool_link">
    <visual>
      <geometry>
        <box size="0.01 0.01 0.01"/>
      </geometry>
      <origin rpy="0 0 0" xyz="0 0 0"/>
    </visual>
    <inertial>
      <mass value="0.0"/>
      <origin rpy="0 0 0" xyz="0.0 0.0 0.0"/>
      <inertia ixx="0.0" ixy="0.0" ixz="0.0" iyy="0.0" iyz="0.0" izz="0.0"/>
    </inertial>
  </link>


  <!-- ######################################### Robotiq 85 ####################################### -->
  <!-- nothing to do here at the moment -->
  <!-- ROS base_link to UR 'Base' Coordinates transform -->

  <!--link name="base_link_robotiq">
    <origin xyz="0 0 0"/>
    <inertial>
      <mass value="0.001"/>
      <origin rpy="0 0 0" xyz="0 0 0"/>
      <inertia ixx="0" ixy="0.0" ixz="0.0" iyy="0.0" iyz="0.0" izz="0.0"/>
    </inertial>
  </link-->

  <!-- base -->
  <joint name="base_link_robotiq_2f_85_base_joint" type="fixed">
    <origin rpy="0 0 0" xyz="0 0 0"/>
    <parent link="ee_link"/>
    <child link="robotiq_2f_85_base"/>
  </joint>

  <link name="robotiq_2f_85_base">
    <inertial>
      <mass value="0.1"/>
      <origin xyz="0 0 0.055"/>
      <inertia ixx="0.000190833333333" ixy="0" ixz="0" iyy="0.00018" iyz="0" izz="0.000190833333333"/>
    </inertial>
    <visual>
      <geometry>
        <mesh filename="gripper/robotiq-2f-base.obj" scale="0.1 0.1 0.1"/>
      </geometry>
      <material name="Blanc"/>
    </visual>
    <!-- <collision>
      <geometry>
        <mesh filename="gripper/robotiq-2f-base.stl" scale="0.001 0.001 0.001"/>
      </geometry>
    </collision> -->
  </link>

   <!-- right finger -->
   <joint name="robotiq_2f_85_right_driver_joint" type="revolute">
     <origin rpy="0 0 0" xyz="0 0.0306011 0.054904"/>
     <parent link="robotiq_2f_85_base"/>
     <child link="robotiq_2f_85_right_driver"/>
     <axis xyz="1 0 0"/>
     <limit effort="60" lower="0.0" upper="0.834" velocity="1.91986177778"/>
   </joint>
   <link name="robotiq_2f_85_right_driver">
     <inertial>
       <mass value="0.1"/>
       <origin xyz="0 0 0.055"/>
       <inertia ixx="0.000190833333333" ixy="0" ixz="0" iyy="0.00018" iyz="0" izz="0.000190833333333"/>
     </inertial>
     <visual>
       <geometry>
         <mesh filename="gripper/robotiq-2f-driver.obj" scale="0.1 0.1 0.1"/>
       </geometry>
       <material name="Blanc"/>
     </visual>
     <!-- <collision>
       <geometry>
         <mesh filename="gripper/robotiq-2f-driver.stl" scale="0.001 0.001 0.001"/>
       </geometry>
     </collision> -->
   </link>

  <joint name="robotiq_2f_85_right_coupler_joint" type="fixed">
     <origin rpy="0 0 0" xyz="0 0.0315 -0.0041"/>
     <parent link="robotiq_2f_85_right_driver"/>
     <child link="robotiq_2f_85_right_coupler"/>
  </joint>

  <link name="robotiq_2f_85_right_coupler">
   <inertial>
     <mass value="0.1"/>
     <origin xyz="0 0 0.055"/>
     <inertia ixx="0.000190833333333" ixy="0" ixz="0" iyy="0.00018" iyz="0" izz="0.000190833333333"/>
   </inertial>
   <visual>
     <geometry>
       <mesh filename="gripper/robotiq-2f-coupler.obj" scale="0.1 0.1 0.1"/>
     </geometry>
     <material name="Blanc"/>
   </visual>
   <!-- <collision>
     <geometry>
       <mesh filename="gripper/robotiq-2f-coupler.stl" scale="0.001 0.001 0.001"/>
     </geometry>
   </collision> -->
  </link>

  <joint name="robotiq_2f_85_right_follower_joint" type="revolute">
   <origin rpy="0 0 0" xyz="0 0.0061 0.0471"/>
   <parent link="robotiq_2f_85_right_coupler"/>
   <child link="robotiq_2f_85_right_follower"/>
   <axis xyz="1 0 0"/>
   <limit effort="176" lower="-2.96705911111" upper="2.96705911111" velocity="1.91986177778"/>
   <mimic joint="robotiq_2f_85_right_driver_joint" multiplier="-1"/>
  </joint>

  <link name="robotiq_2f_85_right_follower">
   <visual>
     <geometry>
       <mesh filename="gripper/robotiq-2f-follower.obj" scale="0.1 0.1 0.1"/>
     </geometry>
     <material name="Tactile_1"/>
   </visual>
   <collision>
     <geometry>
       <mesh filename="gripper/robotiq-2f-follower.stl" scale="0.001 0.001 0.001"/>
     </geometry>
   </collision>
   <inertial>
     <mass value="0.1"/>
     <origin xyz="0 0 0.055"/>
     <inertia ixx="0.000190833333333" ixy="0" ixz="0" iyy="0.00018" iyz="0" izz="0.000190833333333"/>
   </inertial>
  </link>

  <joint name="robotiq_2f_85_right_pad_joint" type="fixed">
   <origin rpy="0 0 0" xyz="0 0.01 0.0"/>
   <parent link="robotiq_2f_85_right_follower"/>
   <child link="robotiq_2f_85_right_pad"/>
  </joint>

  <link name="robotiq_2f_85_right_pad">
   <inertial>
     <mass value="0.1"/>
     <origin xyz="0 0 0.055"  />
     <inertia ixx="0.00019" iyy="0.00018" izz="0.00019" ixy="0" iyz="0" ixz="0"/>
   </inertial>
   <visual>
     <geometry>
         <mesh filename="gripper/robotiq-2f-pad.stl" scale="0.001 0.001 0.001"/>
     </geometry>
     <material name="Tactile_2"/>
   </visual>
   <collision>
     <geometry>
         <mesh filename="gripper/robotiq-2f-pad.stl" scale="0.001 0.001 0.001"/>
     </geometry>
   </collision>
  </link>

  <joint name="robotiq_2f_85_right_spring_link_joint" type="revolute">
   <origin rpy="0 0 0" xyz="0 0.012 0.0614"/>
   <parent link="robotiq_2f_85_base"/>
   <child link="robotiq_2f_85_right_spring_link"/>
   <axis xyz="1 0 0"/>
   <limit effort="176" lower="-2.96705911111" upper="2.96705911111" velocity="1.91986177778"/>
   <mimic joint="robotiq_2f_85_right_driver_joint" multiplier="1"/>
  </joint>

  <link name="robotiq_2f_85_right_spring_link">
   <inertial>
     <mass value="0.1"/>
     <origin xyz="0 0 0.055"/>
     <inertia ixx="0.000190833333333" ixy="0" ixz="0" iyy="0.00018" iyz="0" izz="0.000190833333333"/>
   </inertial>
   <visual>
     <geometry>
       <mesh filename="gripper/robotiq-2f-spring_link.obj" scale="0.1 0.1 0.1"/>
     </geometry>
     <material name="Blanc"/>
   </visual>
   <collision>
     <geometry>
       <mesh filename="gripper/robotiq-2f-spring_link.stl" scale="0.001 0.001 0.001"/>
     </geometry>
   </collision>
  </link>

  <!-- left finger -->
  <joint name="robotiq_2f_85_left_driver_joint" type="revolute">
   <origin rpy="0 0 3.141592653589793" xyz="0 -0.0306011 0.054904"/>
   <parent link="robotiq_2f_85_base"/>
   <child link="robotiq_2f_85_left_driver"/>
   <axis xyz="1 0 0"/>
   <limit effort="176" lower="0.0" upper="0.834" velocity="1.91986177778"/>
   <mimic joint="robotiq_2f_85_right_driver_joint" multiplier="1"/>
  </joint>

  <link name="robotiq_2f_85_left_driver">
   <inertial>
     <mass value="0.1"/>
     <origin xyz="0 0 0.055"/>
     <inertia ixx="0.000190833333333" ixy="0" ixz="0" iyy="0.00018" iyz="0" izz="0.000190833333333"/>
   </inertial>
   <visual>
     <geometry>
       <mesh filename="gripper/robotiq-2f-driver.obj" scale="0.1 0.1 0.1"/>
     </geometry>
     <material name="Blanc"/>
   </visual>
   <!-- <collision>
     <geometry>
       <mesh filename="gripper/robotiq-2f-driver.stl" scale="0.001 0.001 0.001"/>
     </geometry>
   </collision> -->
  </link>

  <joint name="robotiq_2f_85_left_coupler_joint" type="fixed">
   <origin rpy="0 0 0" xyz="0 0.0315 -0.0041"/>
   <parent link="robotiq_2f_85_left_driver"/>
   <child link="robotiq_2f_85_left_coupler"/>
  </joint>

  <link name="robotiq_2f_85_left_coupler">
   <inertial>
     <mass value="0.1"/>
     <origin xyz="0 0 0.055"/>
     <inertia ixx="0.000190833333333" ixy="0" ixz="0" iyy="0.00018" iyz="0" izz="0.000190833333333"/>
   </inertial>
   <visual>
     <geometry>
       <mesh filename="gripper/robotiq-2f-coupler.obj" scale="0.1 0.1 0.1"/>
     </geometry>
     <material name="Blanc"/>
   </visual>
   <!-- <collision>
     <geometry>
       <mesh filename="gripper/robotiq-2f-coupler.stl" scale="0.001 0.001 0.001"/>
     </geometry>
   </collision> -->
  </link>

  <joint name="robotiq_2f_85_left_follower_joint" type="revolute">
   <origin rpy="0 0 0" xyz="0 0.0061 0.0471"/>
   <parent link="robotiq_2f_85_left_coupler"/>
   <child link="robotiq_2f_85_left_follower"/>
   <axis xyz="1 0 0"/>
   <limit effort="176" lower="-2.96705911111" upper="2.96705911111" velocity="1.91986177778"/>
   <mimic joint="robotiq_2f_85_right_driver_joint" multiplier="-1"/>
  </joint>

  <link name="robotiq_2f_85_left_follower">
   <visual>
     <geometry>
       <mesh filename="gripper/robotiq-2f-follower.obj" scale="0.1 0.1 0.1"/>
     </geometry>
     <material name="Tactile_1"/>
   </visual>
   <collision>
     <geometry>
       <mesh filename="gripper/robotiq-2f-follower.stl" scale="0.001 0.001 0.001"/>
     </geometry>
   </collision>
   <inertial>
     <mass value="0.1"/>
     <origin xyz="0 0 0.055"/>
     <inertia ixx="0.000190833333333" ixy="0" ixz="0" iyy="0.00018" iyz="0" izz="0.000190833333333"/>
   </inertial>
  </link>

  <joint name="robotiq_2f_85_left_pad_joint" type="fixed">
    <origin rpy="0 0 0" xyz="0 0.01 0.0"/>
    <parent link="robotiq_2f_85_left_follower"/>
    <child link="robotiq_2f_85_left_pad"/>
  </joint>

  <link name="robotiq_2f_85_left_pad">
   <inertial>
       <mass value="0.1"/>
       <origin xyz="0 0 0.055"  />
       <inertia ixx="0.00019" iyy="0.00018" izz="0.00019" ixy="0" iyz="0" ixz="0"/>
   </inertial>
   <visual>
     <geometry>
       <mesh filename="gripper/robotiq-2f-pad.stl" scale="0.001 0.001 0.001"/>
     </geometry>
     <material name="Tactile_2"/>
   </visual>
   <collision>
       <geometry>
           <mesh filename="gripper/robotiq-2f-pad.stl" scale="0.001 0.001 0.001"/>
       </geometry>
   </collision>
  </link>

  <joint name="robotiq_2f_85_left_spring_link_joint" type="revolute">
     <origin rpy="0 0 3.141592653589793" xyz="0 -0.012 0.0614"/>
     <parent link="robotiq_2f_85_base"/>
     <child link="robotiq_2f_85_left_spring_link"/>
     <axis xyz="1 0 0"/>
     <limit effort="176" lower="-2.96705911111" upper="2.96705911111" velocity="1.91986177778"/>
     <mimic joint="robotiq_2f_85_right_driver_joint" multiplier="1"/>
  </joint>

  <link name="robotiq_2f_85_left_spring_link">
   <inertial>
     <mass value="0.1"/>
     <origin xyz="0 0 0.055"/>
     <inertia ixx="0.000190833333333" ixy="0" ixz="0" iyy="0.00018" iyz="0" izz="0.000190833333333"/>
   </inertial>
   <visual>
     <geometry>
       <mesh filename="gripper/robotiq-2f-spring_link.obj" scale="0.1 0.1 0.1"/>
     </geometry>
     <material name="Blanc"/>
   </visual>
   <!-- <collision>
     <geometry>
       <mesh filename="gripper/robotiq-2f-spring_link.stl" scale="0.001 0.001 0.001"/>
     </geometry>
   </collision> -->
  </link>

  <transmission name="robotiq_2f_85_right_driver_trans">
    <type>transmission_interface/SimpleTransmission</type>
    <joint name="robotiq_2f_85_right_driver_joint">
     <hardwareInterface>hardware_interface/PositionJointInterface</hardwareInterface>
    </joint>
    <actuator name="robotiq_2f_85_right_driver_motor">
     <mechanicalReduction>1</mechanicalReduction>
    </actuator>
  </transmission>

  <!-- Frame coincident with all-zeros TCP on UR controller -->
  <!-- <link name="tool0">
    <inertial>
      <mass value="0.0"/>
      <origin rpy="0 0 0" xyz="0.0 0.0 0.0"/>
      <inertia ixx="0.0" ixy="0.0" ixz="0.0" iyy="0.0" iyz="0.0" izz="0.0"/>
    </inertial>
  </link>
  <joint name="wrist_3_link-tool0_fixed_joint" type="fixed">
    <origin rpy="-1.57079632679 0 0" xyz="0 0.0823 0"/>
    <parent link="wrist_3_link"/>
    <child link="tool0"/>
  </joint>
  -->
</robot>
